Workbook

Sheet VenteSLAT_template
A1: Id | B1: Matricule | C1: Nom | D1: Prenom | E1: emailPerso | F1: phoneNumber | G1: IBAN | H1: BIC | I1: TypeArticle | J1: MarqueArticle | K1: TailleArticle | L1: PrixArticle | M1: Lien | N1: Statut | O1: Origine | P1: CreatedTime | Q1: ModifiedTime
A2: =Feuil1!H2 -> 52835 | B2: NULL | C2: NULL | D2: NULL | E2: NULL | F2: NULL | G2: NULL | H2: NULL | I2: =Feuil1!I2 -> Skis Alpin | J2: =Feuil1!J2 -> Rossignol pursuit | K2: =Feuil1!K2 -> 156 cm | L2: =Feuil1!L2 -> 129 | M2: NULL | N2: Réceptionné | O2: FrancoisDesAlpes | P2: 45973.466 | Q2: 45973.466
A3: =Feuil1!H3 -> 52836 | B3: NULL | C3: NULL | D3: NULL | E3: NULL | F3: NULL | G3: NULL | H3: NULL | I3: =Feuil1!I3 -> Skis Alpin | J3: =Feuil1!J3 -> Rossignol pursuit | K3: =Feuil1!K3 -> 156 cm | L3: =Feuil1!L3 -> 129 | M3: NULL | N3: Réceptionné | O3: FrancoisDesAlpes | P3: 45973.466 | Q3: 45973.466
A4: =Feuil1!H4 -> 52837 | B4: NULL | C4: NULL | D4: NULL | E4: NULL | F4: NULL | G4: NULL | H4: NULL | I4: =Feuil1!I4 -> Skis Alpin | J4: =Feuil1!J4 -> Rossignol exp 86 | K4: =Feuil1!K4 -> 167 cm | L4: =Feuil1!L4 -> 245 | M4: NULL | N4: Réceptionné | O4: FrancoisDesAlpes | P4: 45973.466 | Q4: 45973.466
A5: =Feuil1!H5 -> 52838 | B5: NULL | C5: NULL | D5: NULL | E5: NULL | F5: NULL | G5: NULL | H5: NULL | I5: =Feuil1!I5 -> Skis Alpin | J5: =Feuil1!J5 -> Rossignol hero | K5: =Feuil1!K5 -> 175 cm | L5: =Feuil1!L5 -> 245 | M5: NULL | N5: Réceptionné | O5: FrancoisDesAlpes | P5: 45973.466 | Q5: 45973.466
A6: =Feuil1!H6 -> 52839 | B6: NULL | C6: NULL | D6: NULL | E6: NULL | F6: NULL | G6: NULL | H6: NULL | I6: =Feuil1!I6 -> Skis Alpin | J6: =Feuil1!J6 -> Rossignol forza | K6: =Feuil1!K6 -> 171 cm | L6: =Feuil1!L6 -> 145 | M6: NULL | N6: Réceptionné | O6: FrancoisDesAlpes | P6: 45973.466 | Q6: 45973.466
A7: =Feuil1!H7 -> 52840 | B7: NULL | C7: NULL | D7: NULL | E7: NULL | F7: NULL | G7: NULL | H7: NULL | I7: =Feuil1!I7 -> Skis Alpin | J7: =Feuil1!J7 -> Rossignol react | K7: =Feuil1!K7 -> 156 cm | L7: =Feuil1!L7 -> 145 | M7: NULL | N7: Réceptionné | O7: FrancoisDesAlpes | P7: 45973.466 | Q7: 45973.466
A8: =Feuil1!H8 -> 52841 | B8: NULL | C8: NULL | D8: NULL | E8: NULL | F8: NULL | G8: NULL | H8: NULL | I8: =Feuil1!I8 -> Skis Alpin | J8: =Feuil1!J8 -> Rossignol react | K8: =Feuil1!K8 -> 163 cm | L8: =Feuil1!L8 -> 125 | M8: NULL | N8: Réceptionné | O8: FrancoisDesAlpes | P8: 45973.466 | Q8: 45973.466
A9: =Feuil1!H9 -> 52842 | B9: NULL | C9: NULL | D9: NULL | E9: NULL | F9: NULL | G9: NULL | H9: NULL | I9: =Feuil1!I9 -> Skis Alpin | J9: =Feuil1!J9 -> Rossignol forza | K9: =Feuil1!K9 -> 164 cm | L9: =Feuil1!L9 -> 145 | M9: NULL | N9: Réceptionné | O9: FrancoisDesAlpes | P9: 45973.466 | Q9: 45973.466
A10: =Feuil1!H10 -> 52843 | B10: NULL | C10: NULL | D10: NULL | E10: NULL | F10: NULL | G10: NULL | H10: NULL | I10: =Feuil1!I10 -> Skis Alpin | J10: =Feuil1!J10 -> Rossignol wc8 | K10: =Feuil1!K10 -> 155 cm | L10: =Feuil1!L10 -> 149 | M10: NULL | N10: Réceptionné | O10: FrancoisDesAlpes | P10: 45973.466 | Q10: 45973.466
A11: =Feuil1!H11 -> 52844 | B11: NULL | C11: NULL | D11: NULL | E11: NULL | F11: NULL | G11: NULL | H11: NULL | I11: =Feuil1!I11 -> Skis Alpin | J11: =Feuil1!J11 -> Rossignol wc8 | K11: =Feuil1!K11 -> 155 cm | L11: =Feuil1!L11 -> 149 | M11: NULL | N11: Réceptionné | O11: FrancoisDesAlpes | P11: 45973.466 | Q11: 45973.466
A12: =Feuil1!H12 -> 52845 | B12: NULL | C12: NULL | D12: NULL | E12: NULL | F12: NULL | G12: NULL | H12: NULL | I12: =Feuil1!I12 -> Skis Alpin | J12: =Feuil1!J12 -> Rossignol pursuit | K12: =Feuil1!K12 -> 163 cm | L12: =Feuil1!L12 -> 125 | M12: NULL | N12: Réceptionné | O12: FrancoisDesAlpes | P12: 45973.466 | Q12: 45973.466
A13: =Feuil1!H13 -> 52846 | B13: NULL | C13: NULL | D13: NULL | E13: NULL | F13: NULL | G13: NULL | H13: NULL | I13: =Feuil1!I13 -> Skis Alpin | J13: =Feuil1!J13 -> Rossignol pursuit | K13: =Feuil1!K13 -> 170 cm | L13: =Feuil1!L13 -> 125 | M13: NULL | N13: Réceptionné | O13: FrancoisDesAlpes | P13: 45973.466 | Q13: 45973.466
... A633: =Feuil1!H633 -> 55092 | B633: NULL | C633: NULL | D633: NULL | E633: NULL | F633: NULL | G633: NULL | H633: NULL | I633: =Feuil1!I633 -> Chaussures Alpin | J633: =Feuil1!J633 -> nordica hawk | K633: =Feuil1!K633 -> 45 (EU) / 29 (MP) | L633: =Feuil1!L633 -> 55 | M633: NULL | N633: Réceptionné | O633: FrancoisDesAlpes | P633: 45973.466 | Q633: 45973.466

Sheet Feuil1
A1: NUMÉRO | B1: MARQUE | C1: MODÈLE | D1: TAILLE | E1: PRIX | F1: GENRE | H1: Id | I1: TypeArticle | J1: MarqueArticle | K1: TailleArticle | L1: PrixArticle | R1: 25 | S1: 25 (EU) / 16 (MP)
A2: MS52835 | B2: Rossignol | C2: pursuit | D2: 156 | E2: 129 | F2: ski ad | G2: 1 | H2: =SUBSTITUTE(A2,"MS","",1) -> 52835 | I2: =VLOOKUP(F2,O:P,2,FALSE()) -> Skis Alpin | J2: =CONCATENATE(B2," ",C2) -> Rossignol pursuit | K2: =IF(D2<80,VLOOKUP(D2,R:S,2,FALSE()),CONCATENATE(D2," cm")) -> 156 cm | L2: =E2 -> 129 | O2: ski ad | P2: Skis Alpin | R2: 26 | S2: 26 (EU) / 16 (MP)
A3: MS52836 | B3: Rossignol | C3: pursuit | D3: 156 | E3: 129 | F3: ski ad | G3: 1 | H3: =SUBSTITUTE(A3,"MS","",1) -> 52836 | I3: =VLOOKUP(F3,O:P,2,FALSE()) -> Skis Alpin | J3: =CONCATENATE(B3," ",C3) -> Rossignol pursuit | K3: =IF(D3<80,VLOOKUP(D3,R:S,2,FALSE()),CONCATENATE(D3," cm")) -> 156 cm | L3: =E3 -> 129 | O3: ski ad w | P3: Skis Alpin | R3: 27 | S3: 27 (EU) / 17 (MP)
A4: MS52837 | B4: Rossignol | C4: exp 86 | D4: 167 | E4: 245 | F4: ski ad | G4: 1 | H4: =SUBSTITUTE(A4,"MS","",1) -> 52837 | I4: =VLOOKUP(F4,O:P,2,FALSE()) -> Skis Alpin | J4: =CONCATENATE(B4," ",C4) -> Rossignol exp 86 | K4: =IF(D4<80,VLOOKUP(D4,R:S,2,FALSE()),CONCATENATE(D4," cm")) -> 167 cm | L4: =E4 -> 245 | O4: ski ad | P4: Skis Alpin | R4: 28 | S4: 28 (EU) / 17 (MP)
A5: MS52838 | B5: Rossignol | C5: hero | D5: 175 | E5: 245 | F5: ski ad | G5: 1 | H5: =SUBSTITUTE(A5,"MS","",1) -> 52838 | I5: =VLOOKUP(F5,O:P,2,FALSE()) -> Skis Alpin | J5: =CONCATENATE(B5," ",C5) -> Rossignol hero | K5: =IF(D5<80,VLOOKUP(D5,R:S,2,FALSE()),CONCATENATE(D5," cm")) -> 175 cm | L5: =E5 -> 245 | O5: ski jr | P5: Skis Alpin | R5: 29 | S5: 29 (EU) / 18 (MP)
A6: MS52839 | B6: Rossignol | C6: forza | D6: 171 | E6: 145 | F6: ski ad | G6: 1 | H6: =SUBSTITUTE(A6,"MS","",1) -> 52839 | I6: =VLOOKUP(F6,O:P,2,FALSE()) -> Skis Alpin | J6: =CONCATENATE(B6," ",C6) -> Rossignol forza | K6: =IF(D6<80,VLOOKUP(D6,R:S,2,FALSE()),CONCATENATE(D6," cm")) -> 171 cm | L6: =E6 -> 145 | O6: ch ad | P6: Chaussures Alpin | R6: 30 | S6: 30 (EU) / 19 (MP)
A7: MS52840 | B7: Rossignol | C7: react | D7: 156 | E7: 145 | F7: ski ad | G7: 1 | H7: =SUBSTITUTE(A7,"MS","",1) -> 52840 | I7: =VLOOKUP(F7,O:P,2,FALSE()) -> Skis Alpin | J7: =CONCATENATE(B7," ",C7) -> Rossignol react | K7: =IF(D7<80,VLOOKUP(D7,R:S,2,FALSE()),CONCATENATE(D7," cm")) -> 156 cm | L7: =E7 -> 145 | O7: ch jr | P7: Chaussures Alpin | R7: 31 | S7: 31 (EU) / 19 (MP)
A8: MS52841 | B8: Rossignol | C8: react | D8: 163 | E8: 125 | F8: ski ad | G8: 1 | H8: =SUBSTITUTE(A8,"MS","",1) -> 52841 | I8: =VLOOKUP(F8,O:P,2,FALSE()) -> Skis Alpin | J8: =CONCATENATE(B8," ",C8) -> Rossignol react | K8: =IF(D8<80,VLOOKUP(D8,R:S,2,FALSE()),CONCATENATE(D8," cm")) -> 163 cm | L8: =E8 -> 125 | O8: snowb | P8: Snowboard (avec fixation) | R8: 32 | S8: 32 (EU) / 20 (MP)
A9: MS52842 | B9: Rossignol | C9: forza | D9: 164 | E9: 145 | F9: ski ad | G9: 1 | H9: =SUBSTITUTE(A9,"MS","",1) -> 52842 | I9: =VLOOKUP(F9,O:P,2,FALSE()) -> Skis Alpin | J9: =CONCATENATE(B9," ",C9) -> Rossignol forza | K9: =IF(D9<80,VLOOKUP(D9,R:S,2,FALSE()),CONCATENATE(D9," cm")) -> 164 cm | L9: =E9 -> 145 | O9: ski rando | P9: Skis rando | R9: 33 | S9: 33 (EU) / 21 (MP)
A10: MS52843 | B10: Rossignol | C10: wc8 | D10: 155 | E10: 149 | F10: ski ad | G10: 1 | H10: =SUBSTITUTE(A10,"MS","",1) -> 52843 | I10: =VLOOKUP(F10,O:P,2,FALSE()) -> Skis Alpin | J10: =CONCATENATE(B10," ",C10) -> Rossignol wc8 | K10: =IF(D10<80,VLOOKUP(D10,R:S,2,FALSE()),CONCATENATE(D10," cm")) -> 155 cm | L10: =E10 -> 149 | O10: boots | P10: Chaussures Snowboard | R10: 34 | S10: 34 (EU) / 21 (MP)
A11: MS52844 | B11: Rossignol | C11: wc8 | D11: 155 | E11: 149 | F11: ski ad | G11: 1 | H11: =SUBSTITUTE(A11,"MS","",1) -> 52844 | I11: =VLOOKUP(F11,O:P,2,FALSE()) -> Skis Alpin | J11: =CONCATENATE(B11," ",C11) -> Rossignol wc8 | K11: =IF(D11<80,VLOOKUP(D11,R:S,2,FALSE()),CONCATENATE(D11," cm")) -> 155 cm | L11: =E11 -> 149 | R11: 35 | S11: 35 (EU) / 22 (MP)
A12: MS52845 | B12: Rossignol | C12: pursuit | D12: 163 | E12: 125 | F12: ski ad | G12: 1 | H12: =SUBSTITUTE(A12,"MS","",1) -> 52845 | I12: =VLOOKUP(F12,O:P,2,FALSE()) -> Skis Alpin | J12: =CONCATENATE(B12," ",C12) -> Rossignol pursuit | K12: =IF(D12<80,VLOOKUP(D12,R:S,2,FALSE()),CONCATENATE(D12," cm")) -> 163 cm | L12: =E12 -> 125 | R12: 36 | S12: 36 (EU) / 23 (MP)
A13: MS52846 | B13: Rossignol | C13: pursuit | D13: 170 | E13: 125 | F13: ski ad | G13: 1 | H13: =SUBSTITUTE(A13,"MS","",1) -> 52846 | I13: =VLOOKUP(F13,O:P,2,FALSE()) -> Skis Alpin | J13: =CONCATENATE(B13," ",C13) -> Rossignol pursuit | K13: =IF(D13<80,VLOOKUP(D13,R:S,2,FALSE()),CONCATENATE(D13," cm")) -> 170 cm | L13: =E13 -> 125 | R13: 37 | S13: 37 (EU) / 23 (MP)
A14: MS52847 | B14: volkl | C14: rtm | D14: 177 | E14: 145 | F14: ski ad | G14: 1 | H14: =SUBSTITUTE(A14,"MS","",1) -> 52847 | I14: =VLOOKUP(F14,O:P,2,FALSE()) -> Skis Alpin | J14: =CONCATENATE(B14," ",C14) -> volkl rtm | K14: =IF(D14<80,VLOOKUP(D14,R:S,2,FALSE()),CONCATENATE(D14," cm")) -> 177 cm | L14: =E14 -> 145 | R14: 38 | S14: 38 (EU) / 24 (MP)
A15: MS52848 | B15: volkl | C15: deacon | D15: 161 | E15: 145 | F15: ski ad | G15: 1 | H15: =SUBSTITUTE(A15,"MS","",1) -> 52848 | I15: =VLOOKUP(F15,O:P,2,FALSE()) -> Skis Alpin | J15: =CONCATENATE(B15," ",C15) -> volkl deacon | K15: =IF(D15<80,VLOOKUP(D15,R:S,2,FALSE()),CONCATENATE(D15," cm")) -> 161 cm | L15: =E15 -> 145 | R15: 39 | S15: 39 (EU) / 25 (MP)
A16: MS52849 | B16: volkl | C16: deacon | D16: 161 | E16: 145 | F16: ski ad | G16: 1 | H16: =SUBSTITUTE(A16,"MS","",1) -> 52849 | I16: =VLOOKUP(F16,O:P,2,FALSE()) -> Skis Alpin | J16: =CONCATENATE(B16," ",C16) -> volkl deacon | K16: =IF(D16<80,VLOOKUP(D16,R:S,2,FALSE()),CONCATENATE(D16," cm")) -> 161 cm | L16: =E16 -> 145 | R16: 40 | S16: 40 (EU) / 25 (MP)
A17: MS52850 | B17: volkl | C17: deacon | D17: 175 | E17: 145 | F17: ski ad | G17: 1 | H17: =SUBSTITUTE(A17,"MS","",1) -> 52850 | I17: =VLOOKUP(F17,O:P,2,FALSE()) -> Skis Alpin | J17: =CONCATENATE(B17," ",C17) -> volkl deacon | K17: =IF(D17<80,VLOOKUP(D17,R:S,2,FALSE()),CONCATENATE(D17," cm")) -> 175 cm | L17: =E17 -> 145 | R17: 41 | S17: 41 (EU) / 26 (MP)
A18: MS52851 | B18: volkl | C18: deacon | D18: 175 | E18: 145 | F18: ski ad | G18: 1 | H18: =SUBSTITUTE(A18,"MS","",1) -> 52851 | I18: =VLOOKUP(F18,O:P,2,FALSE()) -> Skis Alpin | J18: =CONCATENATE(B18," ",C18) -> volkl deacon | K18: =IF(D18<80,VLOOKUP(D18,R:S,2,FALSE()),CONCATENATE(D18," cm")) -> 175 cm | L18: =E18 -> 145 | R18: 42 | S18: 42 (EU) / 26 (MP)
A19: MS52852 | B19: volkl | C19: deacon | D19: 172 | E19: 145 | F19: ski ad | G19: 1 | H19: =SUBSTITUTE(A19,"MS","",1) -> 52852 | I19: =VLOOKUP(F19,O:P,2,FALSE()) -> Skis Alpin | J19: =CONCATENATE(B19," ",C19) -> volkl deacon | K19: =IF(D19<80,VLOOKUP(D19,R:S,2,FALSE()),CONCATENATE(D19," cm")) -> 172 cm | L19: =E19 -> 145 | R19: 42.5 | S19: 42.5 (EU) / 27 (MP)
A20: MS52853 | B20: volkl | C20: deacon | D20: 165 | E20: 145 | F20: ski ad | G20: 1 | H20: =SUBSTITUTE(A20,"MS","",1) -> 52853 | I20: =VLOOKUP(F20,O:P,2,FALSE()) -> Skis Alpin | J20: =CONCATENATE(B20," ",C20) -> volkl deacon | K20: =IF(D20<80,VLOOKUP(D20,R:S,2,FALSE()),CONCATENATE(D20," cm")) -> 165 cm | L20: =E20 -> 145 | R20: 43 | S20: 43 (EU) / 27 (MP)
A21: MS52854 | B21: Rossignol | C21: hero | D21: 167 | E21: 245 | F21: ski ad | G21: 1 | H21: =SUBSTITUTE(A21,"MS","",1) -> 52854 | I21: =VLOOKUP(F21,O:P,2,FALSE()) -> Skis Alpin | J21: =CONCATENATE(B21," ",C21) -> Rossignol hero | K21: =IF(D21<80,VLOOKUP(D21,R:S,2,FALSE()),CONCATENATE(D21," cm")) -> 167 cm | L21: =E21 -> 245 | R21: 44 | S21: 44 (EU) / 28 (MP)
A22: MS52855 | B22: Rossignol | C22: pursuit | D22: 170 | E22: 149 | F22: ski ad | G22: 1 | H22: =SUBSTITUTE(A22,"MS","",1) -> 52855 | I22: =VLOOKUP(F22,O:P,2,FALSE()) -> Skis Alpin | J22: =CONCATENATE(B22," ",C22) -> Rossignol pursuit | K22: =IF(D22<80,VLOOKUP(D22,R:S,2,FALSE()),CONCATENATE(D22," cm")) -> 170 cm | L22: =E22 -> 149 | R22: 44.5 | S22: 44.5 (EU) / 28 (MP)
... A27: MS52860 | B27: Rossignol | C27: react | D27: 156 | E27: 129 | F27: ski ad | G27: 1 | H27: =SUBSTITUTE(A27,"MS","",1) -> 52860 | I27: =VLOOKUP(F27,O:P,2,FALSE()) -> Skis Alpin | J27: =CONCATENATE(B27," ",C27) -> Rossignol react | K27: =IF(D27<80,VLOOKUP(D27,R:S,2,FALSE()),CONCATENATE(D27," cm")) -> 156 cm | L27: =E27 -> 129 | R27: 48 | S27: 48 (EU) / 31 (MP)
A28: MS52861 | B28: dynastar | C28: speed 4x4 | D28: 179 | E28: 149 | F28: ski ad | G28: 1 | H28: =SUBSTITUTE(A28,"MS","",1) -> 52861 | I28: =VLOOKUP(F28,O:P,2,FALSE()) -> Skis Alpin | J28: =CONCATENATE(B28," ",C28) -> dynastar speed 4x4 | K28: =IF(D28<80,VLOOKUP(D28,R:S,2,FALSE()),CONCATENATE(D28," cm")) -> 179 cm | L28: =E28 -> 149
A29: MS52862 | B29: dynastar | C29: speed 4x4 | D29: 164 | E29: 169 | F29: ski ad | G29: 1 | H29: =SUBSTITUTE(A29,"MS","",1) -> 52862 | I29: =VLOOKUP(F29,O:P,2,FALSE()) -> Skis Alpin | J29: =CONCATENATE(B29," ",C29) -> dynastar speed 4x4 | K29: =IF(D29<80,VLOOKUP(D29,R:S,2,FALSE()),CONCATENATE(D29," cm")) -> 164 cm | L29: =E29 -> 169
A30: MS52863 | B30: dynastar | C30: speed z10 | D30: 167 | E30: 149 | F30: ski ad | G30: 1 | H30: =SUBSTITUTE(A30,"MS","",1) -> 52863 | I30: =VLOOKUP(F30,O:P,2,FALSE()) -> Skis Alpin | J30: =CONCATENATE(B30," ",C30) -> dynastar speed z10 | K30: =IF(D30<80,VLOOKUP(D30,R:S,2,FALSE()),CONCATENATE(D30," cm")) -> 167 cm | L30: =E30 -> 149
A31: MS52864 | B31: elan | C31: ripstick | D31: 177 | E31: 149 | F31: ski ad | G31: 1 | H31: =SUBSTITUTE(A31,"MS","",1) -> 52864 | I31: =VLOOKUP(F31,O:P,2,FALSE()) -> Skis Alpin | J31: =CONCATENATE(B31," ",C31) -> elan ripstick | K31: =IF(D31<80,VLOOKUP(D31,R:S,2,FALSE()),CONCATENATE(D31," cm")) -> 177 cm | L31: =E31 -> 149
A32: MS52865 | B32: elan | C32: ripstick | D32: 172 | E32: 129 | F32: ski ad | G32: 1 | H32: =SUBSTITUTE(A32,"MS","",1) -> 52865 | I32: =VLOOKUP(F32,O:P,2,FALSE()) -> Skis Alpin | J32: =CONCATENATE(B32," ",C32) -> elan ripstick | K32: =IF(D32<80,VLOOKUP(D32,R:S,2,FALSE()),CONCATENATE(D32," cm")) -> 172 cm | L32: =E32 -> 129
A33: MS52866 | B33: elan | C33: amphibio | D33: 168 | E33: 129 | F33: ski ad | G33: 1 | H33: =SUBSTITUTE(A33,"MS","",1) -> 52866 | I33: =VLOOKUP(F33,O:P,2,FALSE()) -> Skis Alpin | J33: =CONCATENATE(B33," ",C33) -> elan amphibio | K33: =IF(D33<80,VLOOKUP(D33,R:S,2,FALSE()),CONCATENATE(D33," cm")) -> 168 cm | L33: =E33 -> 129
A34: MS52867 | B34: elan | C34: amphibio | D34: 168 | E34: 129 | F34: ski ad | G34: 1 | H34: =SUBSTITUTE(A34,"MS","",1) -> 52867 | I34: =VLOOKUP(F34,O:P,2,FALSE()) -> Skis Alpin | J34: =CONCATENATE(B34," ",C34) -> elan amphibio | K34: =IF(D34<80,VLOOKUP(D34,R:S,2,FALSE()),CONCATENATE(D34," cm")) -> 168 cm | L34: =E34 -> 129
A35: MS52868 | B35: elan | C35: amphibio | D35: 160 | E35: 129 | F35: ski ad | G35: 1 | H35: =SUBSTITUTE(A35,"MS","",1) -> 52868 | I35: =VLOOKUP(F35,O:P,2,FALSE()) -> Skis Alpin | J35: =CONCATENATE(B35," ",C35) -> elan amphibio | K35: =IF(D35<80,VLOOKUP(D35,R:S,2,FALSE()),CONCATENATE(D35," cm")) -> 160 cm | L35: =E35 -> 129
A36: MS52869 | B36: elan | C36: ripstick | D36: 164 | E36: 145 | F36: ski ad | G36: 1 | H36: =SUBSTITUTE(A36,"MS","",1) -> 52869 | I36: =VLOOKUP(F36,O:P,2,FALSE()) -> Skis Alpin | J36: =CONCATENATE(B36," ",C36) -> elan ripstick | K36: =IF(D36<80,VLOOKUP(D36,R:S,2,FALSE()),CONCATENATE(D36," cm")) -> 164 cm | L36: =E36 -> 145
A37: MS52870 | B37: elan | C37: ripstick | D37: 158 | E37: 145 | F37: ski ad | G37: 1 | H37: =SUBSTITUTE(A37,"MS","",1) -> 52870 | I37: =VLOOKUP(F37,O:P,2,FALSE()) -> Skis Alpin | J37: =CONCATENATE(B37," ",C37) -> elan ripstick | K37: =IF(D37<80,VLOOKUP(D37,R:S,2,FALSE()),CONCATENATE(D37," cm")) -> 158 cm | L37: =E37 -> 145
A38: MS52871 | B38: elan | C38: ripstick | D38: 152 | E38: 145 | F38: ski ad | G38: 1 | H38: =SUBSTITUTE(A38,"MS","",1) -> 52871 | I38: =VLOOKUP(F38,O:P,2,FALSE()) -> Skis Alpin | J38: =CONCATENATE(B38," ",C38) -> elan ripstick | K38: =IF(D38<80,VLOOKUP(D38,R:S,2,FALSE()),CONCATENATE(D38," cm")) -> 152 cm | L38: =E38 -> 145
A39: MS52872 | B39: elan | C39: ripstick | D39: 158 | E39: 145 | F39: ski ad | G39: 1 | H39: =SUBSTITUTE(A39,"MS","",1) -> 52872 | I39: =VLOOKUP(F39,O:P,2,FALSE()) -> Skis Alpin | J39: =CONCATENATE(B39," ",C39) -> elan ripstick | K39: =IF(D39<80,VLOOKUP(D39,R:S,2,FALSE()),CONCATENATE(D39," cm")) -> 158 cm | L39: =E39 -> 145
... A268: MS54013 | B268: dynastar | C268: salsa | D268: 104 | E268: 55 | F268: ski jr | G268: 1 | H268: =SUBSTITUTE(A268,"MS","",1) -> 54013 | I268: =VLOOKUP(F268,O:P,2,FALSE()) -> Skis Alpin | J268: =CONCATENATE(B268," ",C268) -> dynastar salsa | K268: =IF(D268<80,VLOOKUP(D268,R:S,2,FALSE()),CONCATENATE(D268," cm")) -> 104 cm | L268: =E268 -> 55
A269: MS54014 | B269: starwars | D269: 104 | E269: 55 | F269: ski jr | G269: 1 | H269: =SUBSTITUTE(A269,"MS","",1) -> 54014 | I269: =VLOOKUP(F269,O:P,2,FALSE()) -> Skis Alpin | J269: =CONCATENATE(B269," ",C269) -> starwars | K269: =IF(D269<80,VLOOKUP(D269,R:S,2,FALSE()),CONCATENATE(D269," cm")) -> 104 cm | L269: =E269 -> 55
A270: MS54015 | B270: starwars | D270: 104 | E270: 55 | F270: ski jr | G270: 1 | H270: =SUBSTITUTE(A270,"MS","",1) -> 54015 | I270: =VLOOKUP(F270,O:P,2,FALSE()) -> Skis Alpin | J270: =CONCATENATE(B270," ",C270) -> starwars | K270: =IF(D270<80,VLOOKUP(D270,R:S,2,FALSE()),CONCATENATE(D270," cm")) -> 104 cm | L270: =E270 -> 55
A271: MS54016 | B271: wedze | C271: one b | D271: 100 | E271: 49 | F271: ski jr | G271: 1 | H271: =SUBSTITUTE(A271,"MS","",1) -> 54016 | I271: =VLOOKUP(F271,O:P,2,FALSE()) -> Skis Alpin | J271: =CONCATENATE(B271," ",C271) -> wedze one b | K271: =IF(D271<80,VLOOKUP(D271,R:S,2,FALSE()),CONCATENATE(D271," cm")) -> 100 cm | L271: =E271 -> 49
A272: MS54017 | B272: salomon | C272: candy | D272: 100 | E272: 45 | F272: ski jr | G272: 1 | H272: =SUBSTITUTE(A272,"MS","",1) -> 54017 | I272: =VLOOKUP(F272,O:P,2,FALSE()) -> Skis Alpin | J272: =CONCATENATE(B272," ",C272) -> salomon candy | K272: =IF(D272<80,VLOOKUP(D272,R:S,2,FALSE()),CONCATENATE(D272," cm")) -> 100 cm | L272: =E272 -> 45
...
